Workbook
Name SchemeList: 'Scheme Master'!$B$4:$B$44

Sheet Scheme Master
A1: SCHEME MASTER - PER CANDIDATE RATE
A3: Sr No. | B3: Scheme Name | C3: Per Candidate Rate (₹) | D3: Description | E3: Status
A4: 1 | B4: PMKVY 4.0 | C4: 480 | D4: Pradhan Mantri Kaushal Vikas Yojana | E4: Active
A5: 2 | B5: DDUGKY | C5: 720 | D5: Deen Dayal Upadhyaya Grameen Kaushalya Yojana | E5: Active
A6: 3 | B6: ODOP-RPL | C6: 540 | D6: SSC- Affiliated Scheme
A7: 4 | B7: BSDMA-RPL | C7: 540
A8: 5 | B8: PMAY-G-STT | C8: 720
A9: 6 | B9: VSSY-RPL | C9: 540
A10: 7 | B10: Suryamitra Skill Development Programme | C10: 400
A11: 8 | B11: PMAY-G-RPL | C11: 540
A12: 9 | B12: NON-PMKVY -CSR | C12: 600
A13: 10 | B13: MESC Fee Based | C13: 400
A14: 11 | B14: CSDCI Fee Based | C14: 720
A15: 12 | B15: ITDA-Meity | C15: 400
A16: 13 | B16: Mahajyoti | C16: 600
A17: 14 | B17: (Industry)EPCH-RPL | C17: 360
A18: 15 | B18: CSR | C18: 600
... A47: 47 | B47: PMKUVA | C47: 420
A48: =A47+1 -> 48 | B48: PMKVY-SP-GIF-Mass Employment Jobrole | C48: 480
A49: =A48+1 -> 49 | B49: TOT - PMVK-Advance | C49: 70 | D49: Gems and Jewellery
A50: =A49+1 -> 50 | B50: SANKALP | C50: 400
A51: =A50+1 -> 51 | B51: SDIS-DDU-GKY | C51: 400
A52: =A51+1 -> 52 | B52: SDIS-ORISSA STATE SKILLING SCHEME | C52: 400
A53: =A52+1 -> 53 | B53: SKILL HUB INITIATIVE | C53: 480
A54: =A53+1 -> 54 | B54: Short Term Training | C54: 480
A55: =A54+1 -> 55 | B55: Special Projects | C55: 480
A56: =A55+1 -> 56 | B56: SSC Affiliated: Skill Council for Green Jobs | C56: 400
A57: =A56+1 -> 57 | B57: TOA | C57: 400
A58: =A57+1 -> 58 | B58: TOMA | C58: 600
A59: =A58+1 -> 59 | B59: TOMT | C59: 400
A60: =A59+1 -> 60 | B60: TOMT | C60: 600
A61: =A60+1 -> 61 | B61: TOT | C61: 400
... A70: =A69+1 -> 70 | B70: offline- Oct-2025- 003 | C70: 600
A71: 71 | B71: 3rd Party | C71: 480

Sheet Assessor Master
A1: ASSESSOR MASTER - ON-ROLL ASSESSORS
A3: Sr No. | B3: Assessor Name | C3: Assessor ID | D3: Sector | E3: Phone | F3: Email | G3: Status
A4: 1 | B4: Mohd Haseen | C4: AR10066 | D4: IT-ITeS | E4: 9876543210 | F4: haseen@example.com | G4: Active
A5: 2 | B5: John Assessor | C5: AR10045 | D5: Healthcare | E5: 9876543211 | F5: john@example.com | G5: Active
A6: 3 | B6: Priya Sharma | C6: AR10078 | D6: Electronics | E6: 9876543212 | F6: priya@example.com | G6: Active
A7: 4 | B7: Amit Kumar | C7: AR10092 | D7: Retail | E7: 9876543213 | F7: amit@example.com | G7: Active
A8: 5 | B8: Neha Singh | C8: AR10101 | D8: Beauty & Wellness | E8: 9876543214 | F8: neha@example.com | G8: Active
A10: Note: | B10: Add on-roll assessors here. When an assessor name is entered in the Assessment Tracker, the system auto-detects if they are on-roll. If not found, user must select Freelancer or Special Circumstances.

Sheet Assessment Tracker
A1: Sr No. | B1: Scheme | C1: Batch ID | D1: Day | E1: Sector | F1: Group Status | G1: Job Role | H1: TP Name | I1: District | J1: State | K1: Assessment Start Date | L1: Assessment End Date | M1: Total Candidates | N1: Present | O1: Absent | P1: Male Count | Q1: Female Count | R1: Passed | S1: Failed | T1: Result Date | U1: Result | V1: Pass % | W1: Fail % | X1: Assessor Name | Y1: User ID | Z1: Trainer Name | AA1: Trainer ID | AB1: Rate/Candidate (₹) | AC1: Total Income (₹) | AD1: Assessor Fee (₹) | AE1: TA/DA (₹) | AF1: Total Exp. (₹) | AG1: Profit/Loss (₹) | AH1: Expense % | AI1: Status | AJ1: Remarks | AK1: Assessor Aligned By | AL1: Approved By | AM1: Approval Date | AN1: Decision | AO1: Final Status | AP1: Assessor Invoice | AQ1: Assessor Expenses Tickets | AR1: Payment Status | AS1: Payment Amount | AT1: Payment Reference ID | AU1: Payment Mode | AV1: Payment Slip Uploaded in drive | AW1: Theory Link | AX1: Practical | AY1: Viva
A2: 1 | B2: PM Vishwakarma | C2: 3732880 | D2: Day 6 | E2: Gems and Jewellery | G2: Goldsmith (Sunar)( G&J/N0612 ) | H2: LEARNET SKILLS LIMITED | I2: SARAN | J2: BIHAR | K2: 46113 | L2: 46113 | M2: 34 | N2: 32 | O2: =IF(AND(M2<>"",N2<>""),M2-N2,"") -> 2 | P2: 28 | Q2: =IF(AND(N2<>"",P2<>""),N2-P2,"") -> 4 | R2: 32 | S2: =IF(AND(N2<>"",R2<>""),N2-R2,"") -> 0 | T2: 46113 | U2: Uploaded | V2: =IFERROR(R2/N2,"") -> 1 | W2: =IFERROR(S2/N2,"") -> 0 | X2: Priyanshu Kumar Tiwari | Y2: AR164546 | Z2: Prem Kumar Harishankar Prasad Singh | AA2: TR21465 | AB2: =IFERROR(VLOOKUP(B2,'Scheme Master'!$B$4:$C$79,2,FALSE),"") -> 360 | AC2: =IF(AND(AB2<>"",N2<>""),AB2*N2,"") -> 11520 | AD2: 2000 | AE2: 1000 | AF2: =IF(OR(AD2<>"",AE2<>""),AD2+AE2,"") -> 3000 | AG2: =IF(AND(AC2<>"",AF2<>""),AC2-AF2,"") -> 8520 | AH2: =IF(AND(AC2<>"",AC2>0,AF2<>""),AF2/AC2,"") -> 0.26041667 | AI2: =IF(AH2="","",IF(AF2>AC2,"🔴 Critical - Over Budget",IF(AH2>0.4,"⚠️ Approval Required","✅ Auto-Approved"))) -> ✅ Auto-Approved | AJ2: =IF(AI2="","",IF(AF2>AC2,"URGENT: Expenses exceed total income. Immediate review needed.",IF(AH2>0.4,"Expenses exceed 40% of income. Management approval required.","Within budget. No approval needed."))) -> Within budget. No approval needed. | AK2: Nisha Saifi | AL2: Richa Mehta | AM2: 46108 | AN2: Approved | AO2: =IF(AI2="","",IF(AI2="✅ Auto-Approved","✅ Approved (Auto - Within Budget)",IF(AN2="","⏳ Awaiting Approval",IF(AN2="Approved","✅ Approved by "&AL2&" on "&TEXT(AM2,"mm/dd/yyyy"),IF(AN2="Rejected","❌ Rejected by "&AL2&" - Review Expenses",IF(AN2="Pending Review","🔍 Under Review by "&AL2,IF(AN2="Escalated","⬆️ Escalated - Senior Management Review",""))))))) -> ✅ Approved (Auto - Within Budget) | AP2: Yes | AR2: Not Paid | AX2: https://drive.google.com/drive/folders/11RgGHdXvEN7luxqe-Tvxifm1UIN4WQZl?usp=sharing
A3: 2 | B3: Suryamitra Skill Development Programme | C3: 3732880 | D3: Normal | E3: Green Jobs | G3: Solar PV Installer (Suryamitra)(SGJ/Q0101) | H3: SAIFI HEALING TOUCH RESEARCH BUREAU FOR SOCIAL WELFARE OF INDIA | I3: SRINAGAR | J3: JAMMU AND KASHMIR | K3: 46114 | L3: 46114 | M3: 30 | N3: 30 | O3: =IF(AND(M3<>"",N3<>""),M3-N3,"") -> 0 | P3: 0 | Q3: =IF(AND(N3<>"",P3<>""),N3-P3,"") -> 30 | R3: 30 | S3: =IF(AND(N3<>"",R3<>""),N3-R3,"") -> 0 | T3: 46115 | U3: Uploaded | V3: =IFERROR(R3/N3,"") -> 1 | W3: =IFERROR(S3/N3,"") -> 0 | X3: Wajid bashir | Y3: AR84804 | Z3: Khalda Yousaf | AA3: TR251247 | AB3: =IFERROR(VLOOKUP(B3,'Scheme Master'!$B$4:$C$79,2,FALSE),"") -> 400 | AC3: =IF(AND(AB3<>"",N3<>""),AB3*N3,"") -> 12000 | AF3: =IF(OR(AD3<>"",AE3<>""),AD3+AE3,"") | AG3: =IF(AND(AC3<>"",AF3<>""),AC3-AF3,"") | AH3: =IF(AND(AC3<>"",AC3>0,AF3<>""),AF3/AC3,"") | AI3: =IF(AH3="","",IF(AF3>AC3,"🔴 Critical - Over Budget",IF(AH3>0.4,"⚠️ Approval Required","✅ Auto-Approved"))) | AK3: Nisha Saifi | AL3: Richa Mehta | AO3: =IF(AI3="","",IF(AI3="✅ Auto-Approved","✅ Approved (Auto - Within Budget)",IF(AN3="","⏳ Awaiting Approval",IF(AN3="Approved","✅ Approved by "&AL3&" on "&TEXT(AM3,"mm/dd/yyyy"),IF(AN3="Rejected","❌ Rejected by "&AL3&" - Review Expenses",IF(AN3="Pending Review","🔍 Under Review by "&AL3,IF(AN3="Escalated","⬆️ Escalated - Senior Management Review",""))))))) | AR3: Not Paid
A4: 3 | B4: PMKVY 4.0 | C4: 3735303 | D4: Day 6 | E4: Gems and Jewellery | G4: Goldsmith (Sunar)( G&J/N0612 ) | H4: NG MANI COLLEGE | I4: IMPHAL EAST | J4: MANIPUR | K4: 46114 | L4: 46114 | M4: 23 | N4: 19 | O4: =IF(AND(M4<>"",N4<>""),M4-N4,"") -> 4 | P4: 14 | Q4: =IF(AND(N4<>"",P4<>""),N4-P4,"") -> 5 | R4: 19 | S4: =IF(AND(N4<>"",R4<>""),N4-R4,"") -> 0 | T4: 46114 | U4: Uploaded | V4: =IFERROR(R4/N4,"") -> 1 | W4: =IFERROR(S4/N4,"") -> 0 | X4: Surjit Sapam | Y4: AR78791 | Z4: Nirmala Yumnam | AA4: TR386536 | AB4: =IFERROR(VLOOKUP(B4,'Scheme Master'!$B$4:$C$79,2,FALSE),"") -> 480 | AC4: =IF(AND(AB4<>"",N4<>""),AB4*N4,"") -> 9120 | AD4: 2000 | AF4: =IF(OR(AD4<>"",AE4<>""),AD4+AE4,"") -> 2000 | AG4: =IF(AND(AC4<>"",AF4<>""),AC4-AF4,"") -> 7120 | AH4: =IF(AND(AC4<>"",AC4>0,AF4<>""),AF4/AC4,"") -> 0.21929825 | AI4: =IF(AH4="","",IF(AF4>AC4,"🔴 Critical - Over Budget",IF(AH4>0.4,"⚠️ Approval Required","✅ Auto-Approved"))) -> ✅ Auto-Approved | AJ4: =IF(AI4="","",IF(AF4>AC4,"URGENT: Expenses exceed total income. Immediate review needed.",IF(AH4>0.4,"Expenses exceed 40% of income. Management approval required.","Within budget. No approval needed."))) -> Within budget. No approval needed. | AK4: Nisha Saifi | AL4: Richa Mehta | AO4: =IF(AI4="","",IF(AI4="✅ Auto-Approved","✅ Approved (Auto - Within Budget)",IF(AN4="","⏳ Awaiting Approval",IF(AN4="Approved","✅ Approved by "&AL4&" on "&TEXT(AM4,"mm/dd/yyyy"),IF(AN4="Rejected","❌ Rejected by "&AL4&" - Review Expenses",IF(AN4="Pending Review","🔍 Under Review by "&AL4,IF(AN4="Escalated","⬆️ Escalated - Senior Management Review",""))))))) -> ✅ Approved (Auto - Within Budget) | AP4: Yes | AR4: Not Paid
A5: 4 | B5: PM Vishwakarma | C5: 3733981 | D5: Day 6 | E5: Construction | G5: Brick Mason -Basic( CON/N0160 ) | H5: TOOL ROOM & TRAINING CENTRE | I5: KAMRUP | J5: ASSAM | K5: 46114 | L5: 46114 | M5: 24 | N5: 20 | O5: =IF(AND(M5<>"",N5<>""),M5-N5,"") -> 4 | P5: 20 | Q5: =IF(AND(N5<>"",P5<>""),N5-P5,"") -> 0 | R5: 20 | S5: =IF(AND(N5<>"",R5<>""),N5-R5,"") -> 0 | T5: 46114 | U5: Uploaded | V5: =IFERROR(R5/N5,"") -> 1 | W5: =IFERROR(S5/N5,"") -> 0 | X5: Satyajit Dash | Y5: AR113593 | Z5: Partha Jyoti Sarmah | AA5: TR633887 | AB5: =IFERROR(VLOOKUP(B5,'Scheme Master'!$B$4:$C$79,2,FALSE),"") -> 360 | AC5: =IF(AND(AB5<>"",N5<>""),AB5*N5,"") -> 7200 | AD5: 2000 | AF5: =IF(OR(AD5<>"",AE5<>""),AD5+AE5,"") -> 2000 | AG5: =IF(AND(AC5<>"",AF5<>""),AC5-AF5,"") -> 5200 | AH5: =IF(AND(AC5<>"",AC5>0,AF5<>""),AF5/AC5,"") -> 0.27777778 | AI5: =IF(AH5="","",IF(AF5>AC5,"🔴 Critical - Over Budget",IF(AH5>0.4,"⚠️ Approval Required","✅ Auto-Approved"))) -> ✅ Auto-Approved | AK5: Harpreet Kaur | AL5: Richa Mehta | AO5: =IF(AI5="","",IF(AI5="✅ Auto-Approved","✅ Approved (Auto - Within Budget)",IF(AN5="","⏳ Awaiting Approval",IF(AN5="Approved","✅ Approved by "&AL5&" on "&TEXT(AM5,"mm/dd/yyyy"),IF(AN5="Rejected","❌ Rejected by "&AL5&" - Review Expenses",IF(AN5="Pending Review","🔍 Under Review by "&AL5,IF(AN5="Escalated","⬆️ Escalated - Senior Management Review",""))))))) -> ✅ Approved (Auto - Within Budget) | AP5: Yes | AR5: Not Paid
A6: 5 | B6: PM Vishwakarma | C6: 3739308 | D6: Day 0 | E6: Handicraft | G6: Traditional Basket Maker( HCS/N9206 ) | H6: Government ITI, Farrukhabad | I6: FARRUKHABAD | J6: UTTAR PRADESH | K6: 46114 | L6: 46114 | M6: 23 | N6: 15 | O6: =IF(AND(M6<>"",N6<>""),M6-N6,"") -> 8 | P6: 9 | Q6: =IF(AND(N6<>"",P6<>""),N6-P6,"") -> 6 | R6: 15 | S6: =IF(AND(N6<>"",R6<>""),N6-R6,"") -> 0 | T6: 46114 | U6: Uploaded | V6: =IFERROR(R6/N6,"") -> 1 | W6: =IFERROR(S6/N6,"") -> 0 | X6: Laxmi Tiwari | Y6: AR135976 | Z6: Laxmi Tiwari | AA6: TR558148 | AB6: =IFERROR(VLOOKUP(B6,'Scheme Master'!$B$4:$C$79,2,FALSE),"") -> 360 | AC6: =IF(AND(AB6<>"",N6<>""),AB6*N6,"") -> 5400 | AD6: 2000 | AF6: =IF(OR(AD6<>"",AE6<>""),AD6+AE6,"") -> 2000 | AG6: =IF(AND(AC6<>"",AF6<>""),AC6-AF6,"") -> 3400 | AH6: =IF(AND(AC6<>"",AC6>0,AF6<>""),AF6/AC6,"") -> 0.37037037 | AI6: =IF(AH6="","",IF(AF6>AC6,"🔴 Critical - Over Budget",IF(AH6>0.4,"⚠️ Approval Required","✅ Auto-Approved"))) -> ✅ Auto-Approved | AJ6: =IF(AI6="","",IF(AF6>AC6,"URGENT: Expenses exceed total income. Immediate review needed.",IF(AH6>0.4,"Expenses exceed 40% of income. Management approval required.","Within budget. No approval needed."))) -> Within budget. No approval needed. | AO6: =IF(AI6="","",IF(AI6="✅ Auto-Approved","✅ Approved (Auto - Within Budget)",IF(AN6="","⏳ Awaiting Approval",IF(AN6="Approved","✅ Approved by "&AL6&" on "&TEXT(AM6,"mm/dd/yyyy"),IF(AN6="Rejected","❌ Rejected by "&AL6&" - Review Expenses",IF(AN6="Pending Review","🔍 Under Review by "&AL6,IF(AN6="Escalated","⬆️ Escalated - Senior Management Review",""))))))) -> ✅ Approved (Auto - Within Budget) | AP6: Yes | AR6: Not Paid
A7: 6 | B7: PM Vishwakarma | C7: 3756354 | D7: Day 0 | E7: Handicraft | G7: Traditional Soft Toy Maker( HCS/N7355 ) | H7: VISION INDIA SERVICES PRIVATE LIMITED | I7: BEGUSARAI | J7: BIHAR | K7: 46114 | L7: 46114 | M7: 8 | N7: 8 | O7: =IF(AND(M7<>"",N7<>""),M7-N7,"") -> 0 | P7: 0 | Q7: =IF(AND(N7<>"",P7<>""),N7-P7,"") -> 8 | R7: 8 | S7: =IF(AND(N7<>"",R7<>""),N7-R7,"") -> 0 | T7: 46114 | U7: Uploaded | V7: =IFERROR(R7/N7,"") -> 1 | W7: =IFERROR(S7/N7,"") -> 0 | X7: Kajal Kumari | Y7: AR154274 | Z7: Kajal Kumari | AA7: TR598635 | AB7: =IFERROR(VLOOKUP(B7,'Scheme Master'!$B$4:$C$79,2,FALSE),"") -> 360 | AC7: =IF(AND(AB7<>"",N7<>""),AB7*N7,"") -> 2880 | AD7: 800 | AF7: =IF(OR(AD7<>"",AE7<>""),AD7+AE7,"") -> 800 | AG7: =IF(AND(AC7<>"",AF7<>""),AC7-AF7,"") -> 2080 | AH7: =IF(AND(AC7<>"",AC7>0,AF7<>""),AF7/AC7,"") -> 0.27777778 | AI7: =IF(AH7="","",IF(AF7>AC7,"🔴 Critical - Over Budget",IF(AH7>0.4,"⚠️ Approval Required","✅ Auto-Approved"))) -> ✅ Auto-Approved | AJ7: =IF(AI7="","",IF(AF7>AC7,"URGENT: Expenses exceed total income. Immediate review needed.",IF(AH7>0.4,"Expenses exceed 40% of income. Management approval required.","Within budget. No approval needed."))) -> Within budget. No approval needed. | AO7: =IF(AI7="","",IF(AI7="✅ Auto-Approved","✅ Approved (Auto - Within Budget)",IF(AN7="","⏳ Awaiting Approval",IF(AN7="Approved","✅ Approved by "&AL7&" on "&TEXT(AM7,"mm/dd/yyyy"),IF(AN7="Rejected","❌ Rejected by "&AL7&" - Review Expenses",IF(AN7="Pending Review","🔍 Under Review by "&AL7,IF(AN7="Escalated","⬆️ Escalated - Senior Management Review",""))))))) -> ✅ Approved (Auto - Within Budget) | AP7: Yes | AR7: Not Paid
A8: 7 | B8: PM Vishwakarma | C8: 3739384 | D8: Day 0 | E8: Construction | G8: Brick Mason -Basic( CON/N0160 ) | H8: ORION EDUTECH PRIVATE LIMITED | I8: DARRANG | J8: ASSAM | K8: postpone | L8: Postpone | M8: 41 | O8: =IF(AND(M8<>"",N8<>""),M8-N8,"") | Q8: =IF(AND(N8<>"",P8<>""),N8-P8,"") | S8: =IF(AND(N8<>"",R8<>""),N8-R8,"") | V8: =IFERROR(R8/N8,"") | W8: =IFERROR(S8/N8,"") | AB8: =IFERROR(VLOOKUP(B8,'Scheme Master'!$B$4:$C$79,2,FALSE),"") -> 360 | AC8: =IF(AND(AB8<>"",N8<>""),AB8*N8,"") | AF8: =IF(OR(AD8<>"",AE8<>""),AD8+AE8,"") | AG8: =IF(AND(AC8<>"",AF8<>""),AC8-AF8,"") | AH8: =IF(AND(AC8<>"",AC8>0,AF8<>""),AF8/AC8,"") | AI8: =IF(AH8="","",IF(AF8>AC8,"🔴 Critical - Over Budget",IF(AH8>0.4,"⚠️ Approval Required","✅ Auto-Approved"))) | AO8: =IF(AI8="","",IF(AI8="✅ Auto-Approved","✅ Approved (Auto - Within Budget)",IF(AN8="","⏳ Awaiting Approval",IF(AN8="Approved","✅ Approved by "&AL8&" on "&TEXT(AM8,"mm/dd/yyyy"),IF(AN8="Rejected","❌ Rejected by "&AL8&" - Review Expenses",IF(AN8="Pending Review","🔍 Under Review by "&AL8,IF(AN8="Escalated","⬆️ Escalated - Senior Management Review","")))))))
A9: 8 | B9: DDUGKY | C9: 3466403 | D9: Day 1 | E9: Construction | G9: Assistant Electrician V3(CON/Q0602) | H9: Lala Kundan Lal Memorial Training Centre | I9: Fatehabad | J9: Haryana | K9: 46115 | L9: 46116 | M9: 35 | N9: 27 | O9: =IF(AND(M9<>"",N9<>""),M9-N9,"") -> 8 | P9: 13 | Q9: =IF(AND(N9<>"",P9<>""),N9-P9,"") -> 14 | R9: 26 | S9: =IF(AND(N9<>"",R9<>""),N9-R9,"") -> 1 | T9: 46118 | U9: Uploaded | V9: =IFERROR(R9/N9,"") -> 0.96296296 | W9: =IFERROR(S9/N9,"") -> 0.037037037 | X9: Mohd Navi | Y9: AR2351 | Z9: Not Available | AA9: Not Available | AB9: =IFERROR(VLOOKUP(B9,'Scheme Master'!$B$4:$C$79,2,FALSE),"") -> 720 | AC9: =IF(AND(AB9<>"",N9<>""),AB9*N9,"") -> 19440 | AF9: =IF(OR(AD9<>"",AE9<>""),AD9+AE9,"") | AG9: =IF(AND(AC9<>"",AF9<>""),AC9-AF9,"") | AH9: =IF(AND(AC9<>"",AC9>0,AF9<>""),AF9/AC9,"") | AI9: =IF(AH9="","",IF(AF9>AC9,"🔴 Critical - Over Budget",IF(AH9>0.4,"⚠️ Approval Required","✅ Auto-Approved"))) | AJ9: =IF(AI9="","",IF(AF9>AC9,"URGENT: Expenses exceed total income. Immediate review needed.",IF(AH9>0.4,"Expenses exceed 40% of income. Management approval required.","Within budget. No approval needed."))) | AO9: =IF(AI9="","",IF(AI9="✅ Auto-Approved","✅ Approved (Auto - Within Budget)",IF(AN9="","⏳ Awaiting Approval",IF(AN9="Approved","✅ Approved by "&AL9&" on "&TEXT(AM9,"mm/dd/yyyy"),IF(AN9="Rejected","❌ Rejected by "&AL9&" - Review Expenses",IF(AN9="Pending Review","🔍 Under Review by "&AL9,IF(AN9="Escalated","⬆️ Escalated - Senior Management Review",""))))))) | AR9: Not Paid
A10: 9 | B10: PM Vishwakarma | C10: 3734797 | D10: Day 6 | E10: Construction | G10: Brick Mason -Basic( CON/N0160 ) | H10: Government Polytechnic college Bandipora | I10: BANDIPORA | J10: JAMMU AND KASHMIR | K10: 46115 | L10: 46115 | M10: 6 | N10: 5 | O10: =IF(AND(M10<>"",N10<>""),M10-N10,"") -> 1 | P10: 5 | Q10: =IF(AND(N10<>"",P10<>""),N10-P10,"") -> 0 | R10: 5 | S10: =IF(AND(N10<>"",R10<>""),N10-R10,"") -> 0 | T10: 46115 | U10: Uploaded | V10: =IFERROR(R10/N10,"") -> 1 | W10: =IFERROR(S10/N10,"") -> 0 | X10: Mudasir Nisar | Y10: AR53637 | Z10: Arifa Bashir | AA10: TR472161 | AB10: =IFERROR(VLOOKUP(B10,'Scheme Master'!$B$4:$C$79,2,FALSE),"") -> 360 | AC10: =IF(AND(AB10<>"",N10<>""),AB10*N10,"") -> 1800 | AF10: =IF(OR(AD10<>"",AE10<>""),AD10+AE10,"") | AG10: =IF(AND(AC10<>"",AF10<>""),AC10-AF10,"") | AH10: =IF(AND(AC10<>"",AC10>0,AF10<>""),AF10/AC10,"") | AI10: =IF(AH10="","",IF(AF10>AC10,"🔴 Critical - Over Budget",IF(AH10>0.4,"⚠️ Approval Required","✅ Auto-Approved"))) | AO10: =IF(AI10="","",IF(AI10="✅ Auto-Approved","✅ Approved (Auto - Within Budget)",IF(AN10="","⏳ Awaiting Approval",IF(AN10="Approved","✅ Approved by "&AL10&" on "&TEXT(AM10,"mm/dd/yyyy"),IF(AN10="Rejected","❌ Rejected by "&AL10&" - Review Expenses",IF(AN10="Pending Review","🔍 Under Review by "&AL10,IF(AN10="Escalated","⬆️ Escalated - Senior Management Review",""))))))) | AR10: Not Paid
A11: 10 | B11: PMKVY 4.0 | C11: 3736126 | D11: Normal | E11: Construction | G11: Fabricator v5.0(CON/Q1206) | H11: Larsen & Toubro Limited | I11: MAYURBHANJ | J11: Odisha | K11: 46115 | L11: 46115 | M11: 28 | N11: 27 | O11: =IF(AND(M11<>"",N11<>""),M11-N11,"") -> 1 | P11: 27 | Q11: =IF(AND(N11<>"",P11<>""),N11-P11,"") -> 0 | R11: 27 | S11: =IF(AND(N11<>"",R11<>""),N11-R11,"") -> 0 | T11: 46116 | U11: Uploaded | V11: =IFERROR(R11/N11,"") -> 1 | W11: =IFERROR(S11/N11,"") -> 0 | X11: Vishal Verma | Y11: A-00E1F0 | Z11: Surya prakash Updhyay | AA11: TR672540 | AB11: =IFERROR(VLOOKUP(B11,'Scheme Master'!$B$4:$C$79,2,FALSE),"") -> 480 | AC11: =IF(AND(AB11<>"",N11<>""),AB11*N11,"") -> 12960 | AF11: =IF(OR(AD11<>"",AE11<>""),AD11+AE11,"") | AG11: =IF(AND(AC11<>"",AF11<>""),AC11-AF11,"") | AH11: =IF(AND(AC11<>"",AC11>0,AF11<>""),AF11/AC11,"") | AI11: =IF(AH11="","",IF(AF11>AC11,"🔴 Critical - Over Budget",IF(AH11>0.4,"⚠️ Approval Required","✅ Auto-Approved"))) | AJ11: =IF(AI11="","",IF(AF11>AC11,"URGENT: Expenses exceed total income. Immediate review needed.",IF(AH11>0.4,"Expenses exceed 40% of income. Management approval required.","Within budget. No approval needed."))) | AO11: =IF(AI11="","",IF(AI11="✅ Auto-Approved","✅ Approved (Auto - Within Budget)",IF(AN11="","⏳ Awaiting Approval",IF(AN11="Approved","✅ Approved by "&AL11&" on "&TEXT(AM11,"mm/dd/yyyy"),IF(AN11="Rejected","❌ Rejected by "&AL11&" - Review Expenses",IF(AN11="Pending Review","🔍 Under Review by "&AL11,IF(AN11="Escalated","⬆️ Escalated - Senior Management Review",""))))))) | AR11: Not Paid
A12: 11 | B12: PM Vishwakarma | C12: 3756600 | D12: Day 0 | E12: Gems and Jewellery | G12: goldsmith (Sunar)( G&J/N0612 ) | H12: NG MANI COLLEGE | I12: IMPHAL EAST | J12: MANIPUR | K12: 46115 | L12: 46115 | M12: 22 | N12: 15 | O12: =IF(AND(M12<>"",N12<>""),M12-N12,"") -> 7 | P12: 11 | Q12: =IF(AND(N12<>"",P12<>""),N12-P12,"") -> 4 | R12: 15 | S12: =IF(AND(N12<>"",R12<>""),N12-R12,"") -> 0 | T12: 46115 | U12: Uploaded | V12: =IFERROR(R12/N12,"") -> 1 | W12: =IFERROR(S12/N12,"") -> 0 | X12: Nirmala Yumnam Chanu | Y12: AR78961 | Z12: Nirmala Yumnam Chanu | AA12: TR386536 | AB12: =IFERROR(VLOOKUP(B12,'Scheme Master'!$B$4:$C$79,2,FALSE),"") -> 360 | AC12: =IF(AND(AB12<>"",N12<>""),AB12*N12,"") -> 5400 | AD12: 2000 | AF12: =IF(OR(AD12<>"",AE12<>""),AD12+AE12,"") -> 2000 | AG12: =IF(AND(AC12<>"",AF12<>""),AC12-AF12,"") -> 3400 | AH12: =IF(AND(AC12<>"",AC12>0,AF12<>""),AF12/AC12,"") -> 0.37037037 | AI12: =IF(AH12="","",IF(AF12>AC12,"🔴 Critical - Over Budget",IF(AH12>0.4,"⚠️ Approval Required","✅ Auto-Approved"))) -> ✅ Auto-Approved | AJ12: =IF(AI12="","",IF(AF12>AC12,"URGENT: Expenses exceed total income. Immediate review needed.",IF(AH12>0.4,"Expenses exceed 40% of income. Management approval required.","Within budget. No approval needed."))) -> Within budget. No approval needed. | AO12: =IF(AI12="","",IF(AI12="✅ Auto-Approved","✅ Approved (Auto - Within Budget)",IF(AN12="","⏳ Awaiting Approval",IF(AN12="Approved","✅ Approved by "&AL12&" on "&TEXT(AM12,"mm/dd/yyyy"),IF(AN12="Rejected","❌ Rejected by "&AL12&" - Review Expenses",IF(AN12="Pending Review","🔍 Under Review by "&AL12,IF(AN12="Escalated","⬆️ Escalated - Senior Management Review",""))))))) -> ✅ Approved (Auto - Within Budget) | AP12: Yes | AR12: Not Paid
A13: 12 | B13: PM Vishwakarma | C13: 3756452 | D13: Day 0 | E13: Gems and Jewellery | G13: goldsmith (Sunar)( G&J/N0612 ) | H13: Government ITI, Sirathu, Kaushambi | I13: KAUSHAMBI | J13: UTTAR PRADESH | K13: 46115 | L13: 46115 | M13: 2 | N13: 2 | O13: =IF(AND(M13<>"",N13<>""),M13-N13,"") -> 0 | P13: 2 | Q13: =IF(AND(N13<>"",P13<>""),N13-P13,"") -> 0 | R13: 2 | S13: =IF(AND(N13<>"",R13<>""),N13-R13,"") -> 0 | T13: 46115 | U13: Uploaded | V13: =IFERROR(R13/N13,"") -> 1 | W13: =IFERROR(S13/N13,"") -> 0 | X13: Anand Kumar | Y13: AR153752 | Z13: Anand Kumar | AA13: TR597173 | AB13: =IFERROR(VLOOKUP(B13,'Scheme Master'!$B$4:$C$79,2,FALSE),"") -> 360 | AC13: =IF(AND(AB13<>"",N13<>""),AB13*N13,"") -> 720 | AD13: 200 | AF13: =IF(OR(AD13<>"",AE13<>""),AD13+AE13,"") -> 200 | AG13: =IF(AND(AC13<>"",AF13<>""),AC13-AF13,"") -> 520 | AH13: =IF(AND(AC13<>"",AC13>0,AF13<>""),AF13/AC13,"") -> 0.27777778 | AI13: =IF(AH13="","",IF(AF13>AC13,"🔴 Critical - Over Budget",IF(AH13>0.4,"⚠️ Approval Required","✅ Auto-Approved"))) -> ✅ Auto-Approved | AJ13: =IF(AI13="","",IF(AF13>AC13,"URGENT: Expenses exceed total income. Immediate review needed.",IF(AH13>0.4,"Expenses exceed 40% of income. Management approval required.","Within budget. No approval needed."))) -> Within budget. No approval needed. | AO13: =IF(AI13="","",IF(AI13="✅ Auto-Approved","✅ Approved (Auto - Within Budget)",IF(AN13="","⏳ Awaiting Approval",IF(AN13="Approved","✅ Approved by "&AL13&" on "&TEXT(AM13,"mm/dd/yyyy"),IF(AN13="Rejected","❌ Rejected by "&AL13&" - Review Expenses",IF(AN13="Pending Review","🔍 Under Review by "&AL13,IF(AN13="Escalated","⬆️ Escalated - Senior Management Review",""))))))) -> ✅ Approved (Auto - Within Budget) | AP13: Yes | AR13: Not Paid
A14: 13 | B14: PMKVY 4.0 | C14: 3739936 | D14: Normal | E14: Green Jobs | G14: Junior Technician - Mechanized Sewer Cleaning(SGJ/Q4006) | H14: NATIONAL SAFAI KARAMCHARIS FINANCE AND DEVELOPMENT CORPORATION | I14: AHMEDABAD | J14: GUJARAT | K14: 46116 | L14: 46116 | M14: 24 | N14: 20 | O14: =IF(AND(M14<>"",N14<>""),M14-N14,"") -> 4 | P14: 18 | Q14: =IF(AND(N14<>"",P14<>""),N14-P14,"") -> 2 | R14: 20 | S14: =IF(AND(N14<>"",R14<>""),N14-R14,"") -> 0 | T14: 46118 | U14: Uploaded | V14: =IFERROR(R14/N14,"") -> 1 | W14: =IFERROR(S14/N14,"") -> 0 | X14: Gaurav patel | Y14: AR180975 | Z14: Ambuj Tripathi | AA14: TR654284 | AB14: =IFERROR(VLOOKUP(B14,'Scheme Master'!$B$4:$C$79,2,FALSE),"") -> 480 | AC14: =IF(AND(AB14<>"",N14<>""),AB14*N14,"") -> 9600 | AD14: 2000 | AE14: 1000 | AF14: =IF(OR(AD14<>"",AE14<>""),AD14+AE14,"") -> 3000 | AG14: =IF(AND(AC14<>"",AF14<>""),AC14-AF14,"") -> 6600 | AH14: =IF(AND(AC14<>"",AC14>0,AF14<>""),AF14/AC14,"") -> 0.3125 | AI14: =IF(AH14="","",IF(AF14>AC14,"🔴 Critical - Over Budget",IF(AH14>0.4,"⚠️ Approval Required","✅ Auto-Approved"))) -> ✅ Auto-Approved | AJ14: =IF(AI14="","",IF(AF14>AC14,"URGENT: Expenses exceed total income. Immediate review needed.",IF(AH14>0.4,"Expenses exceed 40% of income. Management approval required.","Within budget. No approval needed."))) -> Within budget. No approval needed. | AK14: Nisha Saifi | AL14: Richa Mehta | AM14: 46113 | AO14: =IF(AI14="","",IF(AI14="✅ Auto-Approved","✅ Approved (Auto - Within Budget)",IF(AN14="","⏳ Awaiting Approval",IF(AN14="Approved","✅ Approved by "&AL14&" on "&TEXT(AM14,"mm/dd/yyyy"),IF(AN14="Rejected","❌ Rejected by "&AL14&" - Review Expenses",IF(AN14="Pending Review","🔍 Under Review by "&AL14,IF(AN14="Escalated","⬆️ Escalated - Senior Management Review",""))))))) -> ✅ Approved (Auto - Within Budget) | AR14: Not Paid
A15: 8 | B15: DDUGKY | C15: 3466403 | D15: Day 2 | E15: Construction | G15: Assistant Electrician V3(CON/Q0602) | H15: Lala Kundan Lal Memorial Training Centre | I15: Fatehabad | J15: Haryana | K15: 46115 | L15: 46116 | M15: 35 | N15: 27 | O15: =IF(AND(M15<>"",N15<>""),M15-N15,"") -> 8 | P15: 13 | Q15: =IF(AND(N15<>"",P15<>""),N15-P15,"") -> 14 | R15: 26 | S15: =IF(AND(N15<>"",R15<>""),N15-R15,"") -> 1 | T15: 46118 | U15: Uploaded | V15: =IFERROR(R15/N15,"") -> 0.96296296 | W15: =IFERROR(S15/N15,"") -> 0.037037037 | X15: Mohd Navi | Y15: AR2351 | Z15: Not Available | AA15: Not Available | AB15: =IFERROR(VLOOKUP(B15,'Scheme Master'!$B$4:$C$79,2,FALSE),"") -> 720 | AC15: =IF(AND(AB15<>"",N15<>""),AB15*N15,"") -> 19440 | AF15: =IF(OR(AD15<>"",AE15<>""),AD15+AE15,"") | AG15: =IF(AND(AC15<>"",AF15<>""),AC15-AF15,"") | AH15: =IF(AND(AC15<>"",AC15>0,AF15<>""),AF15/AC15,"") | AI15: =IF(AH15="","",IF(AF15>AC15,"🔴 Critical - Over Budget",IF(AH15>0.4,"⚠️ Approval Required","✅ Auto-Approved"))) | AJ15: =IF(AI15="","",IF(AF15>AC15,"URGENT: Expenses exceed total income. Immediate review needed.",IF(AH15>0.4,"Expenses exceed 40% of income. Management approval required.","Within budget. No approval needed."))) | AO15: =IF(AI15="","",IF(AI15="✅ Auto-Approved","✅ Approved (Auto - Within Budget)",IF(AN15="","⏳ Awaiting Approval",IF(AN15="Approved","✅ Approved by "&AL15&" on "&TEXT(AM15,"mm/dd/yyyy"),IF(AN15="Rejected","❌ Rejected by "&AL15&" - Review Expenses",IF(AN15="Pending Review","🔍 Under Review by "&AL15,IF(AN15="Escalated","⬆️ Escalated - Senior Management Review",""))))))) | AR15: Not Paid
A16: 14 | B16: VSSY-RPL | C16: GJSCI_VSSY-RPL/2026-02 | D16: Normal | E16: Gems and Jewellery | G16: Jewellery Frame and Component Maker | H16: UPICON | I16: Barabanki | J16: UttarPradesh | K16: 46116 | L16: 46116 | M16: 25 | N16: 21 | O16: =IF(AND(M16<>"",N16<>""),M16-N16,"") -> 4 | P16: 19 | Q16: =IF(AND(N16<>"",P16<>""),N16-P16,"") -> 2 | R16: 21 | S16: =IF(AND(N16<>"",R16<>""),N16-R16,"") -> 0 | T16: 46118 | U16: Uploaded | V16: =IFERROR(R16/N16,"") -> 1 | W16: =IFERROR(S16/N16,"") -> 0 | X16: Mohd Nadeem | Y16: AR29759 | Z16: Mahima Pandey | AA16: TR346258 | AB16: =IFERROR(VLOOKUP(B16,'Scheme Master'!$B$4:$C$79,2,FALSE),"") -> 540 | AC16: =IF(AND(AB16<>"",N16<>""),AB16*N16,"") -> 11340 | AF16: =IF(OR(AD16<>"",AE16<>""),AD16+AE16,"") | AG16: =IF(AND(AC16<>"",AF16<>""),AC16-AF16,"") | AH16: =IF(AND(AC16<>"",AC16>0,AF16<>""),AF16/AC16,"") | AI16: =IF(AH16="","",IF(AF16>AC16,"🔴 Critical - Over Budget",IF(AH16>0.4,"⚠️ Approval Required","✅ Auto-Approved"))) | AJ16: =IF(AI16="","",IF(AF16>AC16,"URGENT: Expenses exceed total income. Immediate review needed.",IF(AH16>0.4,"Expenses exceed 40% of income. Management approval required.","Within budget. No approval needed."))) | AO16: =IF(AI16="","",IF(AI16="✅ Auto-Approved","✅ Approved (Auto - Within Budget)",IF(AN16="","⏳ Awaiting Approval",IF(AN16="Approved","✅ Approved by "&AL16&" on "&TEXT(AM16,"mm/dd/yyyy"),IF(AN16="Rejected","❌ Rejected by "&AL16&" - Review Expenses",IF(AN16="Pending Review","🔍 Under Review by "&AL16,IF(AN16="Escalated","⬆️ Escalated - Senior Management Review",""))))))) | AR16: Not Paid
A17: 15 | B17: BSDMA-RPL | C17: 3727804 | D17: Day 1 | E17: Construction | G17: Masonry of Earthquake-Resistant Building(CON/N0161) | H17: Astric Solutions | I17: Siwan | J17: Bihar | K17: 46116 | L17: 46117 | M17: 25 | N17: 24 | O17: =IF(AND(M17<>"",N17<>""),M17-N17,"") -> 1 | P17: 24 | Q17: =IF(AND(N17<>"",P17<>""),N17-P17,"") -> 0 | R17: 23 | S17: =IF(AND(N17<>"",R17<>""),N17-R17,"") -> 1 | T17: 46119 | U17: Uploaded | V17: =IFERROR(R17/N17,"") -> 0.95833333 | W17: =IFERROR(S17/N17,"") -> 0.041666667 | X17: Mohd Naseem | Y17: AR145441 | Z17: Priyanshu Ranjan Upadhyay | AA17: TR544100 | AB17: =IFERROR(VLOOKUP(B17,'Scheme Master'!$B$4:$C$79,2,FALSE),"") -> 540 | AC17: =IF(AND(AB17<>"",N17<>""),AB17*N17,"") -> 12960 | AD17: 2000 | AE17: 2000 | AF17: =IF(OR(AD17<>"",AE17<>""),AD17+AE17,"") -> 4000 | AG17: =IF(AND(AC17<>"",AF17<>""),AC17-AF17,"") -> 8960 | AH17: =IF(AND(AC17<>"",AC17>0,AF17<>""),AF17/AC17,"") -> 0.30864198 | AI17: =IF(AH17="","",IF(AF17>AC17,"🔴 Critical - Over Budget",IF(AH17>0.4,"⚠️ Approval Required","✅ Auto-Approved"))) -> ✅ Auto-Approved | AJ17: =IF(AI17="","",IF(AF17>AC17,"URGENT: Expenses exceed total income. Immediate review needed.",IF(AH17>0.4,"Expenses exceed 40% of income. Management approval required.","Within budget. No approval needed."))) -> Within budget. No approval needed. | AO17: =IF(AI17="","",IF(AI17="✅ Auto-Approved","✅ Approved (Auto - Within Budget)",IF(AN17="","⏳ Awaiting Approval",IF(AN17="Approved","✅ Approved by "&AL17&" on "&TEXT(AM17,"mm/dd/yyyy"),IF(AN17="Rejected","❌ Rejected by "&AL17&" - Review Expenses",IF(AN17="Pending Review","🔍 Under Review by "&AL17,IF(AN17="Escalated","⬆️ Escalated - Senior Management Review",""))))))) -> ✅ Approved (Auto - Within Budget) | AR17: Not Paid
A18: 16 | B18: PM Vishwakarma | C18: 3735550 | D18: Day 6 | E18: Construction | G18: Brick Mason -Basic( CON/N0160 ) | H18: ALL INDIA SOCIETY FOR ELECTRONICS AND COMPUTER TECHNOLOGY | I18: KATNI | J18: MADHYA PRADESH | K18: 46116 | L18: 46116 | M18: 23 | N18: 20 | O18: =IF(AND(M18<>"",N18<>""),M18-N18,"") -> 3 | P18: 20 | Q18: =IF(AND(N18<>"",P18<>""),N18-P18,"") -> 0 | R18: 20 | S18: =IF(AND(N18<>"",R18<>""),N18-R18,"") -> 0 | T18: 46116 | U18: Uploaded | V18: =IFERROR(R18/N18,"") -> 1 | W18: =IFERROR(S18/N18,"") -> 0 | X18: Girja Shankar Gigoliya | Y18: AR136635 | Z18: Shiv Kumar Choudhary | AA18: TR409060 | AB18: =IFERROR(VLOOKUP(B18,'Scheme Master'!$B$4:$C$79,2,FALSE),"") -> 360 | AC18: =IF(AND(AB18<>"",N18<>""),AB18*N18,"") -> 7200 | AD18: 2000 | AF18: =IF(OR(AD18<>"",AE18<>""),AD18+AE18,"") -> 2000 | AG18: =IF(AND(AC18<>"",AF18<>""),AC18-AF18,"") -> 5200 | AH18: =IF(AND(AC18<>"",AC18>0,AF18<>""),AF18/AC18,"") -> 0.27777778 | AI18: =IF(AH18="","",IF(AF18>AC18,"🔴 Critical - Over Budget",IF(AH18>0.4,"⚠️ Approval Required","✅ Auto-Approved"))) -> ✅ Auto-Approved | AJ18: =IF(AI18="","",IF(AF18>AC18,"URGENT: Expenses exceed total income. Immediate review needed.",IF(AH18>0.4,"Expenses exceed 40% of income. Management approval required.","Within budget. No approval needed."))) -> Within budget. No approval needed. | AO18: =IF(AI18="","",IF(AI18="✅ Auto-Approved","✅ Approved (Auto - Within Budget)",IF(AN18="","⏳ Awaiting Approval",IF(AN18="Approved","✅ Approved by "&AL18&" on "&TEXT(AM18,"mm/dd/yyyy"),IF(AN18="Rejected","❌ Rejected by "&AL18&" - Review Expenses",IF(AN18="Pending Review","🔍 Under Review by "&AL18,IF(AN18="Escalated","⬆️ Escalated - Senior Management Review",""))))))) -> ✅ Approved (Auto - Within Budget) | AP18: Yes | AR18: Not Paid
A19: 17 | B19: PM Vishwakarma | C19: 3756888 | D19: Day 0 | E19: Handicraft | G19: Traditional Basket Maker( HCS/N9206 ) | H19: Govt ITI (LWE) Gidhuar, Jamui | I19: JAMUI | J19: BIHAR | K19: 46116 | L19: 46116 | M19: 18 | N19: 17 | O19: =IF(AND(M19<>"",N19<>""),M19-N19,"") -> 1 | P19: 0 | Q19: =IF(AND(N19<>"",P19<>""),N19-P19,"") -> 17 | R19: 17 | S19: =IF(AND(N19<>"",R19<>""),N19-R19,"") -> 0 | T19: 46116 | U19: Uploaded | V19: =IFERROR(R19/N19,"") -> 1 | W19: =IFERROR(S19/N19,"") -> 0 | X19: Kanhaiya Kumar | Y19: AR115952 | Z19: Kanhaiya Kumar | AA19: TR507370 | AB19: =IFERROR(VLOOKUP(B19,'Scheme Master'!$B$4:$C$79,2,FALSE),"") -> 360 | AC19: =IF(AND(AB19<>"",N19<>""),AB19*N19,"") -> 6120 | AD19: 2000 | AF19: =IF(OR(AD19<>"",AE19<>""),AD19+AE19,"") -> 2000 | AG19: =IF(AND(AC19<>"",AF19<>""),AC19-AF19,"") -> 4120 | AH19: =IF(AND(AC19<>"",AC19>0,AF19<>""),AF19/AC19,"") -> 0.32679739 | AI19: =IF(AH19="","",IF(AF19>AC19,"🔴 Critical - Over Budget",IF(AH19>0.4,"⚠️ Approval Required","✅ Auto-Approved"))) -> ✅ Auto-Approved | AJ19: =IF(AI19="","",IF(AF19>AC19,"URGENT: Expenses exceed total income. Immediate review needed.",IF(AH19>0.4,"Expenses exceed 40% of income. Management approval required.","Within budget. No approval needed."))) -> Within budget. No approval needed. | AO19: =IF(AI19="","",IF(AI19="✅ Auto-Approved","✅ Approved (Auto - Within Budget)",IF(AN19="","⏳ Awaiting Approval",IF(AN19="Approved","✅ Approved by "&AL19&" on "&TEXT(AM19,"mm/dd/yyyy"),IF(AN19="Rejected","❌ Rejected by "&AL19&" - Review Expenses",IF(AN19="Pending Review","🔍 Under Review by "&AL19,IF(AN19="Escalated","⬆️ Escalated - Senior Management Review",""))))))) -> ✅ Approved (Auto - Within Budget) | AP19: Yes | AR19: Not Paid
A20: 18 | B20: PM Vishwakarma | C20: 3755823 | D20: Day 0 | E20: Gems and Jewellery | G20: Goldsmith (Sunar)( G&J/N0612 ) | H20: GOVT WITI SAHARSA | I20: SAHARSA | J20: BIHAR | K20: 46116 | L20: 46116 | M20: 19 | N20: 19 | O20: =IF(AND(M20<>"",N20<>""),M20-N20,"") -> 0 | P20: 9 | Q20: =IF(AND(N20<>"",P20<>""),N20-P20,"") -> 10 | R20: 19 | S20: =IF(AND(N20<>"",R20<>""),N20-R20,"") -> 0 | T20: 46116 | U20: Uploaded | V20: =IFERROR(R20/N20,"") -> 1 | W20: =IFERROR(S20/N20,"") -> 0 | X20: Ashwinee kumar | Y20: AR161851 | Z20: Ashwinee kumar | AA20: TR616427 | AB20: =IFERROR(VLOOKUP(B20,'Scheme Master'!$B$4:$C$79,2,FALSE),"") -> 360 | AC20: =IF(AND(AB20<>"",N20<>""),AB20*N20,"") -> 6840 | AD20: 2000 | AF20: =IF(OR(AD20<>"",AE20<>""),AD20+AE20,"") -> 2000 | AG20: =IF(AND(AC20<>"",AF20<>""),AC20-AF20,"") -> 4840 | AH20: =IF(AND(AC20<>"",AC20>0,AF20<>""),AF20/AC20,"") -> 0.29239766 | AI20: =IF(AH20="","",IF(AF20>AC20,"🔴 Critical - Over Budget",IF(AH20>0.4,"⚠️ Approval Required","✅ Auto-Approved"))) -> ✅ Auto-Approved | AJ20: =IF(AI20="","",IF(AF20>AC20,"URGENT: Expenses exceed total income. Immediate review needed.",IF(AH20>0.4,"Expenses exceed 40% of income. Management approval required.","Within budget. No approval needed."))) -> Within budget. No approval needed. | AO20: =IF(AI20="","",IF(AI20="✅ Auto-Approved","✅ Approved (Auto - Within Budget)",IF(AN20="","⏳ Awaiting Approval",IF(AN20="Approved","✅ Approved by "&AL20&" on "&TEXT(AM20,"mm/dd/yyyy"),IF(AN20="Rejected","❌ Rejected by "&AL20&" - Review Expenses",IF(AN20="Pending Review","🔍 Under Review by "&AL20,IF(AN20="Escalated","⬆️ Escalated - Senior Management Review",""))))))) -> ✅ Approved (Auto - Within Budget) | AP20: Yes | AR20: Not Paid
A21: 19 | B21: PM Vishwakarma | C21: 3739384 | D21: Day 0 | E21: Construction | G21: Brick Mason -Basic( CON/N0160 ) | H21: ORION EDUTECH PRIVATE LIMITED | I21: DARRANG | J21: ASSAM | K21: Postpone | L21: Postpone | M21: 41 | O21: =IF(AND(M21<>"",N21<>""),M21-N21,"") | Q21: =IF(AND(N21<>"",P21<>""),N21-P21,"") | S21: =IF(AND(N21<>"",R21<>""),N21-R21,"") | V21: =IFERROR(R21/N21,"") | W21: =IFERROR(S21/N21,"") | AB21: =IFERROR(VLOOKUP(B21,'Scheme Master'!$B$4:$C$79,2,FALSE),"") -> 360 | AC21: =IF(AND(AB21<>"",N21<>""),AB21*N21,"") | AF21: =IF(OR(AD21<>"",AE21<>""),AD21+AE21,"") | AG21: =IF(AND(AC21<>"",AF21<>""),AC21-AF21,"") | AH21: =IF(AND(AC21<>"",AC21>0,AF21<>""),AF21/AC21,"") | AI21: =IF(AH21="","",IF(AF21>AC21,"🔴 Critical - Over Budget",IF(AH21>0.4,"⚠️ Approval Required","✅ Auto-Approved"))) | AJ21: =IF(AI21="","",IF(AF21>AC21,"URGENT: Expenses exceed total income. Immediate review needed.",IF(AH21>0.4,"Expenses exceed 40% of income. Management approval required.","Within budget. No approval needed."))) | AO21: =IF(AI21="","",IF(AI21="✅ Auto-Approved","✅ Approved (Auto - Within Budget)",IF(AN21="","⏳ Awaiting Approval",IF(AN21="Approved","✅ Approved by "&AL21&" on "&TEXT(AM21,"mm/dd/yyyy"),IF(AN21="Rejected","❌ Rejected by "&AL21&" - Review Expenses",IF(AN21="Pending Review","🔍 Under Review by "&AL21,IF(AN21="Escalated","⬆️ Escalated - Senior Management Review","")))))))
A22: 20 | B22: PMKVY 4.0 | C22: 3727439 | D22: Normal | E22: Green Jobs | G22: Junior Technician - Mechanized Sewer Cleaning(SGJ/Q4006) | H22: Brainlite Education Solutions Pvt Ltd | I22: RAJKOT | J22: GUJARAT | K22: Postpone | L22: Postpone | M22: 38 | O22: =IF(AND(M22<>"",N22<>""),M22-N22,"") | Q22: =IF(AND(N22<>"",P22<>""),N22-P22,"") | S22: =IF(AND(N22<>"",R22<>""),N22-R22,"") | V22: =IFERROR(R22/N22,"") | W22: =IFERROR(S22/N22,"") | AB22: =IFERROR(VLOOKUP(B22,'Scheme Master'!$B$4:$C$79,2,FALSE),"") -> 480 | AC22: =IF(AND(AB22<>"",N22<>""),AB22*N22,"") | AF22: =IF(OR(AD22<>"",AE22<>""),AD22+AE22,"") | AG22: =IF(AND(AC22<>"",AF22<>""),AC22-AF22,"") | AH22: =IF(AND(AC22<>"",AC22>0,AF22<>""),AF22/AC22,"") | AI22: =IF(AH22="","",IF(AF22>AC22,"🔴 Critical - Over Budget",IF(AH22>0.4,"⚠️ Approval Required","✅ Auto-Approved"))) | AJ22: =IF(AI22="","",IF(AF22>AC22,"URGENT: Expenses exceed total income. Immediate review needed.",IF(AH22>0.4,"Expenses exceed 40% of income. Management approval required.","Within budget. No approval needed."))) | AO22: =IF(AI22="","",IF(AI22="✅ Auto-Approved","✅ Approved (Auto - Within Budget)",IF(AN22="","⏳ Awaiting Approval",IF(AN22="Approved","✅ Approved by "&AL22&" on "&TEXT(AM22,"mm/dd/yyyy"),IF(AN22="Rejected","❌ Rejected by "&AL22&" - Review Expenses",IF(AN22="Pending Review","🔍 Under Review by "&AL22,IF(AN22="Escalated","⬆️ Escalated - Senior Management Review","")))))))
A23: 21 | B23: PMKVY 4.0 | C23: 3708112 | D23: Normal | E23: Green Jobs | G23: Swacchta Saarthi( SGJ/MCr-0015) | H23: Shrawani Srivastava | I23: KHAMMAM | J23: TELANGANA | K23: Postpone | L23: Postpone | M23: 44 | O23: =IF(AND(M23<>"",N23<>""),M23-N23,"") | Q23: =IF(AND(N23<>"",P23<>""),N23-P23,"") | S23: =IF(AND(N23<>"",R23<>""),N23-R23,"") | V23: =IFERROR(R23/N23,"") | W23: =IFERROR(S23/N23,"") | AB23: =IFERROR(VLOOKUP(B23,'Scheme Master'!$B$4:$C$79,2,FALSE),"") -> 480 | AC23: =IF(AND(AB23<>"",N23<>""),AB23*N23,"") | AF23: =IF(OR(AD23<>"",AE23<>""),AD23+AE23,"") | AG23: =IF(AND(AC23<>"",AF23<>""),AC23-AF23,"") | AH23: =IF(AND(AC23<>"",AC23>0,AF23<>""),AF23/AC23,"") | AI23: =IF(AH23="","",IF(AF23>AC23,"🔴 Critical - Over Budget",IF(AH23>0.4,"⚠️ Approval Required","✅ Auto-Approved"))) | AJ23: =IF(AI23="","",IF(AF23>AC23,"URGENT: Expenses exceed total income. Immediate review needed.",IF(AH23>0.4,"Expenses exceed 40% of income. Management approval required.","Within budget. No approval needed."))) | AO23: =IF(AI23="","",IF(AI23="✅ Auto-Approved","✅ Approved (Auto - Within Budget)",IF(AN23="","⏳ Awaiting Approval",IF(AN23="Approved","✅ Approved by "&AL23&" on "&TEXT(AM23,"mm/dd/yyyy"),IF(AN23="Rejected","❌ Rejected by "&AL23&" - Review Expenses",IF(AN23="Pending Review","🔍 Under Review by "&AL23,IF(AN23="Escalated","⬆️ Escalated - Senior Management Review","")))))))
A24: 23 | B24: ODOP-RPL | C24: 01042026-27 | D24: Normal | E24: Handicraft | G24: Bamboo Work Artisan | H24: Uttar Pradesh Institute of Design and Research | I24: Amethi | J24: Uttar Pradesh | K24: 46117 | L24: 46117 | M24: 25 | N24: 25 | O24: =IF(AND(M24<>"",N24<>""),M24-N24,"") -> 0 | P24: 0 | Q24: =IF(AND(N24<>"",P24<>""),N24-P24,"") -> 25 | R24: 25 | S24: =IF(AND(N24<>"",R24<>""),N24-R24,"") -> 0 | T24: 46120 | U24: Uploaded | V24: =IFERROR(R24/N24,"") -> 1 | W24: =IFERROR(S24/N24,"") -> 0 | X24: Amit Gangwar | Y24: AR73171 | Z24: Pradeep Kumar Kulshreshtha | AA24: TR587524 | AB24: =IFERROR(VLOOKUP(B24,'Scheme Master'!$B$4:$C$79,2,FALSE),"") -> 540 | AC24: =IF(AND(AB24<>"",N24<>""),AB24*N24,"") -> 13500 | AE24: 1230 | AF24: =IF(OR(AD24<>"",AE24<>""),AD24+AE24,"") -> 1230 | AG24: =IF(AND(AC24<>"",AF24<>""),AC24-AF24,"") -> 12270 | AH24: =IF(AND(AC24<>"",AC24>0,AF24<>""),AF24/AC24,"") -> 0.091111111 | AI24: =IF(AH24="","",IF(AF24>AC24,"🔴 Critical - Over Budget",IF(AH24>0.4,"⚠️ Approval Required","✅ Auto-Approved"))) -> ✅ Auto-Approved | AJ24: =IF(AI24="","",IF(AF24>AC24,"URGENT: Expenses exceed total income. Immediate review needed.",IF(AH24>0.4,"Expenses exceed 40% of income. Management approval required.","Within budget. No approval needed."))) -> Within budget. No approval needed. | AO24: =IF(AI24="","",IF(AI24="✅ Auto-Approved","✅ Approved (Auto - Within Budget)",IF(AN24="","⏳ Awaiting Approval",IF(AN24="Approved","✅ Approved by "&AL24&" on "&TEXT(AM24,"mm/dd/yyyy"),IF(AN24="Rejected","❌ Rejected by "&AL24&" - Review Expenses",IF(AN24="Pending Review","🔍 Under Review by "&AL24,IF(AN24="Escalated","⬆️ Escalated - Senior Management Review",""))))))) -> ✅ Approved (Auto - Within Budget) | AR24: Not Paid
A25: 24 | B25: ODOP-RPL | C25: 01042026-28 | D25: Normal | E25: Handicraft | G25: Bamboo Work Artisan | H25: Uttar Pradesh Institute of Design and Research | I25: Amethi | J25: Uttar Pradesh | K25: 46117 | L25: 46117 | M25: 25 | N25: 24 | O25: =IF(AND(M25<>"",N25<>""),M25-N25,"") -> 1 | P25: 0 | Q25: =IF(AND(N25<>"",P25<>""),N25-P25,"") -> 24 | R25: 24 | S25: =IF(AND(N25<>"",R25<>""),N25-R25,"") -> 0 | T25: 46120 | U25: Uploaded | V25: =IFERROR(R25/N25,"") -> 1 | W25: =IFERROR(S25/N25,"") -> 0 | X25: Amit Gangwar | Y25: AR73171 | Z25: Pradeep Kumar Kulshreshtha | AA25: TR587524 | AB25: =IFERROR(VLOOKUP(B25,'Scheme Master'!$B$4:$C$79,2,FALSE),"") -> 540 | AC25: =IF(AND(AB25<>"",N25<>""),AB25*N25,"") -> 12960 | AF25: =IF(OR(AD25<>"",AE25<>""),AD25+AE25,"") | AG25: =IF(AND(AC25<>"",AF25<>""),AC25-AF25,"") | AH25: =IF(AND(AC25<>"",AC25>0,AF25<>""),AF25/AC25,"") | AI25: =IF(AH25="","",IF(AF25>AC25,"🔴 Critical - Over Budget",IF(AH25>0.4,"⚠️ Approval Required","✅ Auto-Approved"))) | AJ25: =IF(AI25="","",IF(AF25>AC25,"URGENT: Expenses exceed total income. Immediate review needed.",IF(AH25>0.4,"Expenses exceed 40% of income. Management approval required.","Within budget. No approval needed."))) | AO25: =IF(AI25="","",IF(AI25="✅ Auto-Approved","✅ Approved (Auto - Within Budget)",IF(AN25="","⏳ Awaiting Approval",IF(AN25="Approved","✅ Approved by "&AL25&" on "&TEXT(AM25,"mm/dd/yyyy"),IF(AN25="Rejected","❌ Rejected by "&AL25&" - Review Expenses",IF(AN25="Pending Review","🔍 Under Review by "&AL25,IF(AN25="Escalated","⬆️ Escalated - Senior Management Review",""))))))) | AR25: Not Paid
A26: 25 | B26: PMKVY 4.0 | C26: GJSCI_VSSY-RPL/2026-04 | D26: Normal | E26: Gems and Jewellery | G26: Jewellery Frame and Component Maker | H26: UPICON | I26: Kanpur Nagar | J26: Uttar Pradesh | K26: 46117 | L26: 46117 | M26: 25 | N26: 19 | O26: =IF(AND(M26<>"",N26<>""),M26-N26,"") -> 6 | P26: 18 | Q26: =IF(AND(N26<>"",P26<>""),N26-P26,"") -> 1 | R26: 19 | S26: =IF(AND(N26<>"",R26<>""),N26-R26,"") -> 0 | T26: 46118 | U26: Uploaded | V26: =IFERROR(R26/N26,"") -> 1 | W26: =IFERROR(S26/N26,"") -> 0 | X26: Mohd Nadeem | Y26: AR29759 | Z26: Anju Verma | AA26: TR341602 | AB26: =IFERROR(VLOOKUP(B26,'Scheme Master'!$B$4:$C$79,2,FALSE),"") -> 480 | AC26: =IF(AND(AB26<>"",N26<>""),AB26*N26,"") -> 9120 | AF26: =IF(OR(AD26<>"",AE26<>""),AD26+AE26,"") | AG26: =IF(AND(AC26<>"",AF26<>""),AC26-AF26,"") | AH26: =IF(AND(AC26<>"",AC26>0,AF26<>""),AF26/AC26,"") | AI26: =IF(AH26="","",IF(AF26>AC26,"🔴 Critical - Over Budget",IF(AH26>0.4,"⚠️ Approval Required","✅ Auto-Approved"))) | AJ26: =IF(AI26="","",IF(AF26>AC26,"URGENT: Expenses exceed total income. Immediate review needed.",IF(AH26>0.4,"Expenses exceed 40% of income. Management approval required.","Within budget. No approval needed."))) | AO26: =IF(AI26="","",IF(AI26="✅ Auto-Approved","✅ Approved (Auto - Within Budget)",IF(AN26="","⏳ Awaiting Approval",IF(AN26="Approved","✅ Approved by "&AL26&" on "&TEXT(AM26,"mm/dd/yyyy"),IF(AN26="Rejected","❌ Rejected by "&AL26&" - Review Expenses",IF(AN26="Pending Review","🔍 Under Review by "&AL26,IF(AN26="Escalated","⬆️ Escalated - Senior Management Review",""))))))) | AR26: Not Paid
A27: 26 | B27: PMAY-G-STT | C27: 3583922 | D27: Normal | E27: Construction | G27: Rural Mason V4.0 | H27: Merapath Education Limited | I27: Nandurbar | J27: Maharashtra | K27: 46117 | L27: 46117 | M27: 15 | N27: 15 | O27: =IF(AND(M27<>"",N27<>""),M27-N27,"") -> 0 | P27: 9 | Q27: =IF(AND(N27<>"",P27<>""),N27-P27,"") -> 6 | R27: 14 | S27: =IF(AND(N27<>"",R27<>""),N27-R27,"") -> 1 | T27: 46120 | U27: Uploaded | V27: =IFERROR(R27/N27,"") -> 0.93333333 | W27: =IFERROR(S27/N27,"") -> 0.066666667 | X27: Krishnapal | Y27: AR77228 | Z27: Vijay Meghval | AA27: TR506611 | AB27: =IFERROR(VLOOKUP(B27,'Scheme Master'!$B$4:$C$79,2,FALSE),"") -> 720 | AC27: =IF(AND(AB27<>"",N27<>""),AB27*N27,"") -> 10800 | AF27: =IF(OR(AD27<>"",AE27<>""),AD27+AE27,"") | AG27: =IF(AND(AC27<>"",AF27<>""),AC27-AF27,"") | AH27: =IF(AND(AC27<>"",AC27>0,AF27<>""),AF27/AC27,"") | AI27: =IF(AH27="","",IF(AF27>AC27,"🔴 Critical - Over Budget",IF(AH27>0.4,"⚠️ Approval Required","✅ Auto-Approved"))) | AJ27: =IF(AI27="","",IF(AF27>AC27,"URGENT: Expenses exceed total income. Immediate review needed.",IF(AH27>0.4,"Expenses exceed 40% of income. Management approval required.","Within budget. No approval needed."))) | AO27: =IF(AI27="","",IF(AI27="✅ Auto-Approved","✅ Approved (Auto - Within Budget)",IF(AN27="","⏳ Awaiting Approval",IF(AN27="Approved","✅ Approved by "&AL27&" on "&TEXT(AM27,"mm/dd/yyyy"),IF(AN27="Rejected","❌ Rejected by "&AL27&" - Review Expenses",IF(AN27="Pending Review","🔍 Under Review by "&AL27,IF(AN27="Escalated","⬆️ Escalated - Senior Management Review",""))))))) | AR27: Not Paid
A28: 27 | B28: BSDMA-RPL | C28: 3727804 | D28: Day 2 | E28: Construction | G28: Masonry of Earthquake-Resistant Building | H28: Astric Solutions | I28: Siwan | J28: Bihar | K28: 46116 | L28: 46117 | M28: 25 | N28: 24 | O28: =IF(AND(M28<>"",N28<>""),M28-N28,"") -> 1 | P28: 24 | Q28: =IF(AND(N28<>"",P28<>""),N28-P28,"") -> 0 | R28: 23 | S28: =IF(AND(N28<>"",R28<>""),N28-R28,"") -> 1 | T28: 46119 | U28: Uploaded | V28: =IFERROR(R28/N28,"") -> 0.95833333 | W28: =IFERROR(S28/N28,"") -> 0.041666667 | X28: Mohd Naseem | Y28: AR145441 | Z28: Priyanshu Ranjan Upadhyay | AA28: TR544100 | AB28: =IFERROR(VLOOKUP(B28,'Scheme Master'!$B$4:$C$79,2,FALSE),"") -> 540 | AC28: =IF(AND(AB28<>"",N28<>""),AB28*N28,"") -> 12960 | AF28: =IF(OR(AD28<>"",AE28<>""),AD28+AE28,"") | AG28: =IF(AND(AC28<>"",AF28<>""),AC28-AF28,"") | AH28: =IF(AND(AC28<>"",AC28>0,AF28<>""),AF28/AC28,"") | AI28: =IF(AH28="","",IF(AF28>AC28,"🔴 Critical - Over Budget",IF(AH28>0.4,"⚠️ Approval Required","✅ Auto-Approved"))) | AJ28: =IF(AI28="","",IF(AF28>AC28,"URGENT: Expenses exceed total income. Immediate review needed.",IF(AH28>0.4,"Expenses exceed 40% of income. Management approval required.","Within budget. No approval needed."))) | AO28: =IF(AI28="","",IF(AI28="✅ Auto-Approved","✅ Approved (Auto - Within Budget)",IF(AN28="","⏳ Awaiting Approval",IF(AN28="Approved","✅ Approved by "&AL28&" on "&TEXT(AM28,"mm/dd/yyyy"),IF(AN28="Rejected","❌ Rejected by "&AL28&" - Review Expenses",IF(AN28="Pending Review","🔍 Under Review by "&AL28,IF(AN28="Escalated","⬆️ Escalated - Senior Management Review",""))))))) | AR28: Not Paid
A29: 28 | B29: PM Vishwakarma | C29: 3739641 | D29: Day 0 | E29: Construction | G29: Brick Mason -Basic( CON/N0160 ) | H29: LEARNET SKILLS LIMITED | I29: JAMMU | J29: JAMMU AND KASHMIR | K29: Postpone | L29: Postpone | M29: 45 | O29: =IF(AND(M29<>"",N29<>""),M29-N29,"") | Q29: =IF(AND(N29<>"",P29<>""),N29-P29,"") | S29: =IF(AND(N29<>"",R29<>""),N29-R29,"") | V29: =IFERROR(R29/N29,"") | W29: =IFERROR(S29/N29,"") | AB29: =IFERROR(VLOOKUP(B29,'Scheme Master'!$B$4:$C$79,2,FALSE),"") -> 360 | AC29: =IF(AND(AB29<>"",N29<>""),AB29*N29,"") | AF29: =IF(OR(AD29<>"",AE29<>""),AD29+AE29,"") | AG29: =IF(AND(AC29<>"",AF29<>""),AC29-AF29,"") | AH29: =IF(AND(AC29<>"",AC29>0,AF29<>""),AF29/AC29,"") | AI29: =IF(AH29="","",IF(AF29>AC29,"🔴 Critical - Over Budget",IF(AH29>0.4,"⚠️ Approval Required","✅ Auto-Approved"))) | AJ29: =IF(AI29="","",IF(AF29>AC29,"URGENT: Expenses exceed total income. Immediate review needed.",IF(AH29>0.4,"Expenses exceed 40% of income. Management approval required.","Within budget. No approval needed."))) | AO29: =IF(AI29="","",IF(AI29="✅ Auto-Approved","✅ Approved (Auto - Within Budget)",IF(AN29="","⏳ Awaiting Approval",IF(AN29="Approved","✅ Approved by "&AL29&" on "&TEXT(AM29,"mm/dd/yyyy"),IF(AN29="Rejected","❌ Rejected by "&AL29&" - Review Expenses",IF(AN29="Pending Review","🔍 Under Review by "&AL29,IF(AN29="Escalated","⬆️ Escalated - Senior Management Review","")))))))
A30: 29 | B30: PM Vishwakarma | C30: 3739236 | D30: Day 6 | E30: Construction | G30: Brick Mason -Basic( CON/N0160 ) | H30: CENTRAL TOOL ROOM AND TRAINING CENTRE | I30: KALAHANDI | J30: ODISHA | K30: 46117 | L30: 46117 | M30: 12 | N30: 11 | O30: =IF(AND(M30<>"",N30<>""),M30-N30,"") -> 1 | P30: 11 | Q30: =IF(AND(N30<>"",P30<>""),N30-P30,"") -> 0 | R30: 11 | S30: =IF(AND(N30<>"",R30<>""),N30-R30,"") -> 0 | T30: 46117 | U30: Uploaded | V30: =IFERROR(R30/N30,"") -> 1 | W30: =IFERROR(S30/N30,"") -> 0 | X30: Chittaranjan panda | Y30: AR142325 | Z30: Jaga Prasad Pattnaik | AA30: TR546304 | AB30: =IFERROR(VLOOKUP(B30,'Scheme Master'!$B$4:$C$79,2,FALSE),"") -> 360 | AC30: =IF(AND(AB30<>"",N30<>""),AB30*N30,"") -> 3960 | AD30: 2000 | AE30: 1000 | AF30: =IF(OR(AD30<>"",AE30<>""),AD30+AE30,"") -> 3000 | AG30: =IF(AND(AC30<>"",AF30<>""),AC30-AF30,"") -> 960 | AH30: =IF(AND(AC30<>"",AC30>0,AF30<>""),AF30/AC30,"") -> 0.75757576 | AI30: =IF(AH30="","",IF(AF30>AC30,"🔴 Critical - Over Budget",IF(AH30>0.4,"⚠️ Approval Required","✅ Auto-Approved"))) -> ⚠️ Approval Required | AJ30: =IF(AI30="","",IF(AF30>AC30,"URGENT: Expenses exceed total income. Immediate review needed.",IF(AH30>0.4,"Expenses exceed 40% of income. Management approval required.","Within budget. No approval needed."))) -> Expenses exceed 40% of income. Management approval required. | AK30: Nisha Saifi | AL30: Richa Mehta | AM30: 46114 | AN30: Approved | AO30: =IF(AI30="","",IF(AI30="✅ Auto-Approved","✅ Approved (Auto - Within Budget)",IF(AN30="","⏳ Awaiting Approval",IF(AN30="Approved","✅ Approved by "&AL30&" on "&TEXT(AM30,"mm/dd/yyyy"),IF(AN30="Rejected","❌ Rejected by "&AL30&" - Review Expenses",IF(AN30="Pending Review","🔍 Under Review by "&AL30,IF(AN30="Escalated","⬆️ Escalated - Senior Management Review",""))))))) -> ✅ Approved by Richa Mehta on 04/02/2026 | AR30: Not Paid
A31: =A30+1 -> 30 | B31: PMKVY 4.0 | C31: 3708112 | D31: Normal | E31: Green Jobs | G31: Swacchta Saarthi( SGJ/MCr-0015) | H31: Shrawani Srivastava | I31: KHAMMAM | J31: TELANGANA | K31: 46118 | L31: 46118 | M31: 44 | N31: 43 | O31: =IF(AND(M31<>"",N31<>""),M31-N31,"") -> 1 | P31: 16 | Q31: =IF(AND(N31<>"",P31<>""),N31-P31,"") -> 27 | R31: 43 | S31: =IF(AND(N31<>"",R31<>""),N31-R31,"") -> 0 | T31: 46120 | U31: Uploaded | V31: =IFERROR(R31/N31,"") -> 1 | W31: =IFERROR(S31/N31,"") -> 0 | X31: Kanagala Ramasurekanand | Y31: AR102979 | Z31: Satish Kumar | AA31: TR29766 | AB31: =IFERROR(VLOOKUP(B31,'Scheme Master'!$B$4:$C$79,2,FALSE),"") -> 480 | AC31: =IF(AND(AB31<>"",N31<>""),AB31*N31,"") -> 20640 | AD31: 2000 | AE31: 1000 | AF31: =IF(OR(AD31<>"",AE31<>""),AD31+AE31,"") -> 3000 | AG31: =IF(AND(AC31<>"",AF31<>""),AC31-AF31,"") -> 17640 | AH31: =IF(AND(AC31<>"",AC31>0,AF31<>""),AF31/AC31,"") -> 0.14534884 | AI31: =IF(AH31="","",IF(AF31>AC31,"🔴 Critical - Over Budget",IF(AH31>0.4,"⚠️ Approval Required","✅ Auto-Approved"))) -> ✅ Auto-Approved | AJ31: =IF(AI31="","",IF(AF31>AC31,"URGENT: Expenses exceed total income. Immediate review needed.",IF(AH31>0.4,"Expenses exceed 40% of income. Management approval required.","Within budget. No approval needed."))) -> Within budget. No approval needed. | AK31: Nisha Saifi | AL31: Richa Mehta | AM31: 46117 | AN31: Approved | AO31: =IF(AI31="","",IF(AI31="✅ Auto-Approved","✅ Approved (Auto - Within Budget)",IF(AN31="","⏳ Awaiting Approval",IF(AN31="Approved","✅ Approved by "&AL31&" on "&TEXT(AM31,"mm/dd/yyyy"),IF(AN31="Rejected","❌ Rejected by "&AL31&" - Review Expenses",IF(AN31="Pending Review","🔍 Under Review by "&AL31,IF(AN31="Escalated","⬆️ Escalated - Senior Management Review",""))))))) -> ✅ Approved (Auto - Within Budget) | AR31: Not Paid
A32: =A31+1 -> 31 | B32: ODOP-RPL | C32: 01042026-29 | D32: Normal | E32: Handicraft | G32: Bamboo Work Artisan | H32: Uttar Pradesh Institute of Design and Research | I32: Amethi | J32: Uttar Pradesh | K32: 46118 | L32: 46118 | M32: 25 | N32: 23 | O32: =IF(AND(M32<>"",N32<>""),M32-N32,"") -> 2 | P32: 0 | Q32: =IF(AND(N32<>"",P32<>""),N32-P32,"") -> 23 | R32: 23 | S32: =IF(AND(N32<>"",R32<>""),N32-R32,"") -> 0 | T32: 46120 | U32: Uploaded | V32: =IFERROR(R32/N32,"") -> 1 | W32: =IFERROR(S32/N32,"") -> 0 | X32: Amit Gangwar | Y32: AR73171 | Z32: Pradeep Kumar Kulshreshtha | AA32: TR587524 | AB32: =IFERROR(VLOOKUP(B32,'Scheme Master'!$B$4:$C$79,2,FALSE),"") -> 540 | AC32: =IF(AND(AB32<>"",N32<>""),AB32*N32,"") -> 12420 | AE32: 1230 | AF32: =IF(OR(AD32<>"",AE32<>""),AD32+AE32,"") -> 1230 | AG32: =IF(AND(AC32<>"",AF32<>""),AC32-AF32,"") -> 11190 | AH32: =IF(AND(AC32<>"",AC32>0,AF32<>""),AF32/AC32,"") -> 0.099033816 | AI32: =IF(AH32="","",IF(AF32>AC32,"🔴 Critical - Over Budget",IF(AH32>0.4,"⚠️ Approval Required","✅ Auto-Approved"))) -> ✅ Auto-Approved | AJ32: =IF(AI32="","",IF(AF32>AC32,"URGENT: Expenses exceed total income. Immediate review needed.",IF(AH32>0.4,"Expenses exceed 40% of income. Management approval required.","Within budget. No approval needed."))) -> Within budget. No approval needed. | AO32: =IF(AI32="","",IF(AI32="✅ Auto-Approved","✅ Approved (Auto - Within Budget)",IF(AN32="","⏳ Awaiting Approval",IF(AN32="Approved","✅ Approved by "&AL32&" on "&TEXT(AM32,"mm/dd/yyyy"),IF(AN32="Rejected","❌ Rejected by "&AL32&" - Review Expenses",IF(AN32="Pending Review","🔍 Under Review by "&AL32,IF(AN32="Escalated","⬆️ Escalated - Senior Management Review",""))))))) -> ✅ Approved (Auto - Within Budget) | AR32: Not Paid
A33: =A32+1 -> 32 | B33: ODOP-RPL | C33: 01042026-30 | D33: Normal | E33: Handicraft | G33: Bamboo Work Artisan | H33: Uttar Pradesh Institute of Design and Research | I33: Amethi | J33: Uttar Pradesh | K33: 46118 | L33: 46118 | M33: 25 | N33: 23 | O33: =IF(AND(M33<>"",N33<>""),M33-N33,"") -> 2 | P33: 0 | Q33: =IF(AND(N33<>"",P33<>""),N33-P33,"") -> 23 | R33: 23 | S33: =IF(AND(N33<>"",R33<>""),N33-R33,"") -> 0 | T33: 46120 | U33: Uploaded | V33: =IFERROR(R33/N33,"") -> 1 | W33: =IFERROR(S33/N33,"") -> 0 | X33: Amit Gangwar | Y33: AR73171 | Z33: Pradeep Kumar Kulshreshtha | AA33: TR587524 | AB33: =IFERROR(VLOOKUP(B33,'Scheme Master'!$B$4:$C$79,2,FALSE),"") -> 540 | AC33: =IF(AND(AB33<>"",N33<>""),AB33*N33,"") -> 12420 | AF33: =IF(OR(AD33<>"",AE33<>""),AD33+AE33,"") | AG33: =IF(AND(AC33<>"",AF33<>""),AC33-AF33,"") | AH33: =IF(AND(AC33<>"",AC33>0,AF33<>""),AF33/AC33,"") | AI33: =IF(AH33="","",IF(AF33>AC33,"🔴 Critical - Over Budget",IF(AH33>0.4,"⚠️ Approval Required","✅ Auto-Approved"))) | AJ33: =IF(AI33="","",IF(AF33>AC33,"URGENT: Expenses exceed total income. Immediate review needed.",IF(AH33>0.4,"Expenses exceed 40% of income. Management approval required.","Within budget. No approval needed."))) | AO33: =IF(AI33="","",IF(AI33="✅ Auto-Approved","✅ Approved (Auto - Within Budget)",IF(AN33="","⏳ Awaiting Approval",IF(AN33="Approved","✅ Approved by "&AL33&" on "&TEXT(AM33,"mm/dd/yyyy"),IF(AN33="Rejected","❌ Rejected by "&AL33&" - Review Expenses",IF(AN33="Pending Review","🔍 Under Review by "&AL33,IF(AN33="Escalated","⬆️ Escalated - Senior Management Review",""))))))) | AR33: Not Paid
A34: =A33+1 -> 33 | B34: ODOP-RPL | C34: 01042026-33 | D34: Normal | E34: Handicraft | G34: Traditional Hand Embroiderer | H34: Uttar Pradesh Institute of Design and Research | I34: Lucknow | J34: UttarPradesh | K34: 46118 | L34: 46118 | M34: 25 | N34: 24 | O34: =IF(AND(M34<>"",N34<>""),M34-N34,"") -> 1 | P34: 0 | Q34: =IF(AND(N34<>"",P34<>""),N34-P34,"") -> 24 | R34: 24 | S34: =IF(AND(N34<>"",R34<>""),N34-R34,"") -> 0 | T34: 46120 | U34: Uploaded | V34: =IFERROR(R34/N34,"") -> 1 | W34: =IFERROR(S34/N34,"") -> 0 | X34: Mohd Navi | Y34: AR2351 | Z34: Ritu Singh | AA34: TR353756 | AB34: =IFERROR(VLOOKUP(B34,'Scheme Master'!$B$4:$C$79,2,FALSE),"") -> 540 | AC34: =IF(AND(AB34<>"",N34<>""),AB34*N34,"") -> 12960 | AD34: 2000 | AF34: =IF(OR(AD34<>"",AE34<>""),AD34+AE34,"") -> 2000 | AG34: =IF(AND(AC34<>"",AF34<>""),AC34-AF34,"") -> 10960 | AH34: =IF(AND(AC34<>"",AC34>0,AF34<>""),AF34/AC34,"") -> 0.15432099 | AI34: =IF(AH34="","",IF(AF34>AC34,"🔴 Critical - Over Budget",IF(AH34>0.4,"⚠️ Approval Required","✅ Auto-Approved"))) -> ✅ Auto-Approved | AJ34: =IF(AI34="","",IF(AF34>AC34,"URGENT: Expenses exceed total income. Immediate review needed.",IF(AH34>0.4,"Expenses exceed 40% of income. Management approval required.","Within budget. No approval needed."))) -> Within budget. No approval needed. | AO34: =IF(AI34="","",IF(AI34="✅ Auto-Approved","✅ Approved (Auto - Within Budget)",IF(AN34="","⏳ Awaiting Approval",IF(AN34="Approved","✅ Approved by "&AL34&" on "&TEXT(AM34,"mm/dd/yyyy"),IF(AN34="Rejected","❌ Rejected by "&AL34&" - Review Expenses",IF(AN34="Pending Review","🔍 Under Review by "&AL34,IF(AN34="Escalated","⬆️ Escalated - Senior Management Review",""))))))) -> ✅ Approved (Auto - Within Budget) | AR34: Not Paid
A35: =A34+1 -> 34 | B35: ODOP-RPL | C35: 01042026-34 | D35: Normal | E35: Handicraft | G35: Traditional Hand Embroiderer | H35: Uttar Pradesh Institute of Design and Research | I35: Lucknow | J35: UttarPradesh | K35: 46118 | L35: 46118 | M35: 25 | N35: 22 | O35: =IF(AND(M35<>"",N35<>""),M35-N35,"") -> 3 | P35: 0 | Q35: =IF(AND(N35<>"",P35<>""),N35-P35,"") -> 22 | R35: 22 | S35: =IF(AND(N35<>"",R35<>""),N35-R35,"") -> 0 | T35: 46120 | U35: Uploaded | V35: =IFERROR(R35/N35,"") -> 1 | W35: =IFERROR(S35/N35,"") -> 0 | X35: Mohd Navi | Y35: AR2351 | Z35: Ritu Singh | AA35: TR353756 | AB35: =IFERROR(VLOOKUP(B35,'Scheme Master'!$B$4:$C$79,2,FALSE),"") -> 540 | AC35: =IF(AND(AB35<>"",N35<>""),AB35*N35,"") -> 11880 | AD35: 2000 | AF35: =IF(OR(AD35<>"",AE35<>""),AD35+AE35,"") -> 2000 | AG35: =IF(AND(AC35<>"",AF35<>""),AC35-AF35,"") -> 9880 | AH35: =IF(AND(AC35<>"",AC35>0,AF35<>""),AF35/AC35,"") -> 0.16835017 | AI35: =IF(AH35="","",IF(AF35>AC35,"🔴 Critical - Over Budget",IF(AH35>0.4,"⚠️ Approval Required","✅ Auto-Approved"))) -> ✅ Auto-Approved | AJ35: =IF(AI35="","",IF(AF35>AC35,"URGENT: Expenses exceed total income. Immediate review needed.",IF(AH35>0.4,"Expenses exceed 40% of income. Management approval required.","Within budget. No approval needed."))) -> Within budget. No approval needed. | AO35: =IF(AI35="","",IF(AI35="✅ Auto-Approved","✅ Approved (Auto - Within Budget)",IF(AN35="","⏳ Awaiting Approval",IF(AN35="Approved","✅ Approved by "&AL35&" on "&TEXT(AM35,"mm/dd/yyyy"),IF(AN35="Rejected","❌ Rejected by "&AL35&" - Review Expenses",IF(AN35="Pending Review","🔍 Under Review by "&AL35,IF(AN35="Escalated","⬆️ Escalated - Senior Management Review",""))))))) -> ✅ Approved (Auto - Within Budget) | AR35: Not Paid
